Workbook

Sheet 入力 Inputs
A1: =IF('入力 Inputs'!$F$1="English","PPVA MASTER TOOL — ALL INPUTS",IF('入力 Inputs'!$F$1="日本語","PPVAマスターツール — 全入力項目","PPVAマスターツール — 全入力項目 / PPVA MASTER TOOL — ALL INPUTS")) -> PPVA MASTER TOOL — ALL INPUTS | F1: English
A2: =IF('入力 Inputs'!$F$1="English","Blue = adjustable inputs | Black = auto-calculated | Change inputs here to update",IF('入力 Inputs'!$F$1="日本語","青 = 変更可能な入力 | 黒 = 自動計算 | ここで入力を変更して計算シートを更新","青 = 変更可能な入力 | 黒 = 自動計算 | ここで入力を変更して計算シートを更新 / Blue = adjustable inputs | Black = auto-calculated | Change inputs here to update")) -> Blue = adjustable inputs | Black = auto-calculated | Change inputs here to update
A4: =IF('入力 Inputs'!$F$1="English","POLICY DETAILS",IF('入力 Inputs'!$F$1="日本語","証券詳細","証券詳細 / POLICY DETAILS")) -> POLICY DETAILS
A5: =IF('入力 Inputs'!$F$1="English","Policy Owner",IF('入力 Inputs'!$F$1="日本語","契約者","契約者 / Policy Owner")) -> Policy Owner | B5: Creating Yourself LLC
A6: =IF('入力 Inputs'!$F$1="English","Policy Issue Date",IF('入力 Inputs'!$F$1="日本語","証券発行日","証券発行日 / Policy Issue Date")) -> Policy Issue Date | B6: 46087
A7: =IF('入力 Inputs'!$F$1="English","Total Deposit",IF('入力 Inputs'!$F$1="日本語","預入総額","預入総額 / Total Deposit")) -> Total Deposit | B7: 13000000
A8: =IF('入力 Inputs'!$F$1="English","Policy Type",IF('入力 Inputs'!$F$1="日本語","保険種類","保険種類 / Policy Type")) -> Policy Type | B8: Variable Annuity (PPVA)
A10: =IF('入力 Inputs'!$F$1="English","PREMIUM LOAD (Step 1)",IF('入力 Inputs'!$F$1="日本語","プレミアムロード（ステップ1）","プレミアムロード（ステップ1） / PREMIUM LOAD (Step 1)")) -> PREMIUM LOAD (Step 1)
A11: =IF('入力 Inputs'!$F$1="English","Premium Load %",IF('入力 Inputs'!$F$1="日本語","プレミアムロード率","プレミアムロード率 / Premium Load %")) -> Premium Load % | B11: 0.06 | E11: 6% Premium Load on deposit
A12: =IF('入力 Inputs'!$F$1="English","3cStructures load %",IF('入力 Inputs'!$F$1="日本語","3cStructuresロード率","3cStructuresロード率 / 3cStructures load %")) -> 3cStructures load % | B12: 0.01
A13: =IF('入力 Inputs'!$F$1="English","Syndicated Capital holdback %",IF('入力 Inputs'!$F$1="日本語","Syndicated Capital保持率","Syndicated Capital保持率 / Syndicated Capital holdback %")) -> Syndicated Capital holdback % | B13: 0.05 | E13: ← 0.05 × Premium Load rate
A14: =IF('入力 Inputs'!$F$1="English","PB Investment Services holdback %",IF('入力 Inputs'!$F$1="日本語","PB Investment Services保持率","PB Investment Services保持率 / PB Investment Services holdback %")) -> PB Investment Services holdback % | B14: 0.05 | E14: ← 0.05 × Premium Load rate
A15: =IF('入力 Inputs'!$F$1="English","PBWR split % (of net to PB)",IF('入力 Inputs'!$F$1="日本語","PBWR分配率（PBネットの%）","PBWR分配率（PBネットの%） / PBWR split % (of net to PB)")) -> PBWR split % (of net to PB) | B15: 0.5 | E15: ← 50/50 split to Ohana
A16: =IF('入力 Inputs'!$F$1="English","Ohana share of net load %",IF('入力 Inputs'!$F$1="日本語","Ohanaのネットロード分配率","Ohanaのネットロード分配率 / Ohana share of net load %")) -> Ohana share of net load % | B16: =1-B15 -> 0.5 | E16: Auto = 100% minus PBWR share above
A18: =IF('入力 Inputs'!$F$1="English","ADMIN & BANK FEES (Step 2)",IF('入力 Inputs'!$F$1="日本語","管理・銀行手数料（ステップ2）","管理・銀行手数料（ステップ2） / ADMIN & BANK FEES (Step 2)")) -> ADMIN & BANK FEES (Step 2)
A19: =IF('入力 Inputs'!$F$1="English","Advantage annuity admin fee",IF('入力 Inputs'!$F$1="日本語","Advantage年金管理費","Advantage年金管理費 / Advantage annuity admin fee")) -> Advantage annuity admin fee | B19: 19500 | C19: Net to Fund Projected | D19: Net To Fund Actual | E19: Source: Sam Jensen email communication
A20: =IF('入力 Inputs'!$F$1="English","Misc. bank / setup fees",IF('入力 Inputs'!$F$1="日本語","その他銀行・設定費","その他銀行・設定費 / Misc. bank / setup fees")) -> Misc. bank / setup fees | B20: 1500 | C20: =(B7-(B7*B11)-(B7*B12)-B19-B20)*100% -> 12069000 | D20: 12069000 | E20: Source: Sam Jensen email communication — estimate
A21: Variance | C21: =C20-D20 -> 0
A23: =IF('入力 Inputs'!$F$1="English","Product",IF('入力 Inputs'!$F$1="日本語","商品","商品 / Product")) -> Product | B23: =IF('入力 Inputs'!$F$1="English","Alloc %",IF('入力 Inputs'!$F$1="日本語","配分率","配分率 / Alloc %")) -> Alloc % | C23: =IF('入力 Inputs'!$F$1="English","Amount ($)",IF('入力 Inputs'!$F$1="日本語","金額","金額 / Amount ($)")) -> Amount ($) | D23: =IF('入力 Inputs'!$F$1="English","Est. Rate",IF('入力 Inputs'!$F$1="日本語","推定利率","推定利率 / Est. Rate")) -> Est. Rate | E23: =IF('入力 Inputs'!$F$1="English","Weighted Return",IF('入力 Inputs'!$F$1="日本語","加重リターン","加重リターン / Weighted Return")) -> Weighted Return
A24: =IF('入力 Inputs'!$F$1="English"," GUARANTEED PRODUCTS ("&TEXT(SUM(B25:B27),"0%")&")",IF('入力 Inputs'!$F$1="日本語"," 保証商品 ("&TEXT(SUM(B25:B27),"0%")&")"," 保証商品 / GUARANTEED PRODUCTS ("&TEXT(SUM(B25:B27),"0%")&")")) -> GUARANTEED PRODUCTS (75%)
A25: =IF('入力 Inputs'!$F$1="English","Intl Fixed Rate Plan Plus",IF('入力 Inputs'!$F$1="日本語","国際固定金利プランプラス","国際固定金利プランプラス / Intl Fixed Rate Plan Plus")) -> Intl Fixed Rate Plan Plus | B25: 0.35 | C25: =(B7-(B7*B11)-(B7*B12)-B19-B20)*B25 -> 4224150 | D25: 0.058 | E25: =B25*D25 -> 0.0203
A26: =IF('入力 Inputs'!$F$1="English","Intl Fixed Rate Plan",IF('入力 Inputs'!$F$1="日本語","国際固定金利プラン","国際固定金利プラン / Intl Fixed Rate Plan")) -> Intl Fixed Rate Plan | B26: 0.25 | C26: =(B7-(B7*B11)-(B7*B12)-B19-B20)*B26 -> 3017250 | D26: 0.056 | E26: =B26*D26 -> 0.014
A27: =IF('入力 Inputs'!$F$1="English","US 5-Year FIA (AmFirst / Trailhead)",IF('入力 Inputs'!$F$1="日本語","米国5年FIA","米国5年FIA / US 5-Year FIA (AmFirst / Trailhead)")) -> US 5-Year FIA (AmFirst / Trailhead) | B27: 0.15 | C27: =(B7-(B7*B11)-(B7*B12)-B19-B20)*B27 -> 1810350 | D27: 0.0515 | E27: =B27*D27 -> 0.007725
A28: =IF('入力 Inputs'!$F$1="English"," NON-GUARANTEED ("&TEXT(SUM(B29:B31),"0%")&")",IF('入力 Inputs'!$F$1="日本語"," 非保証 ("&TEXT(SUM(B29:B31),"0%")&")"," 非保証 / NON-GUARANTEED ("&TEXT(SUM(B29:B31),"0%")&")")) -> NON-GUARANTEED (25%)
A29: =IF('入力 Inputs'!$F$1="English","AAIDX (Alt Income)",IF('入力 Inputs'!$F$1="日本語","AAIDX（代替収益）","AAIDX（代替収益） / AAIDX (Alt Income)")) -> AAIDX (Alt Income) | B29: 0.1 | C29: =(B7-(B7*B11)-(B7*B12)-B19-B20)*B29 -> 1206900 | D29: 0.07 | E29: =B29*D29 -> 0.007
A30: =IF('入力 Inputs'!$F$1="English","ACRE III (CRE Fund)",IF('入力 Inputs'!$F$1="日本語","ACRE III（CREファンド）","ACRE III（CREファンド） / ACRE III (CRE Fund)")) -> ACRE III (CRE Fund) | B30: 0.1 | C30: =(B7-(B7*B11)-(B7*B12)-B19-B20)*B30 -> 1206900 | D30: 0.12 | E30: =B30*D30 -> 0.012
A31: =IF('入力 Inputs'!$F$1="English","Cash (Liquidity)",IF('入力 Inputs'!$F$1="日本語","現金（流動性）","現金（流動性） / Cash (Liquidity)")) -> Cash (Liquidity) | B31: 0.05 | C31: =(B7-(B7*B11)-(B7*B12)-B19-B20)*B31 -> 603450 | D31: 0.03 | E31: =B31*D31 -> 0.0015
A32: =IF('入力 Inputs'!$F$1="English","GROSS WEIGHTED TOTAL",IF('入力 Inputs'!$F$1="日本語","加重合計","加重合計 / GROSS WEIGHTED TOTAL")) -> GROSS WEIGHTED TOTAL | B32: =B25+B26+B27+B29+B30+B31 -> 1 | C32: =SUM(C26+C25+C27+C29+C30+C31) -> 12069000 | D32: =AVERAGE(D29:D31,D25:D27) -> 0.06425 | E32: =SUM(E25:E31) -> 0.062525
A34: =IF('入力 Inputs'!$F$1="English","ANNUITY COMMISSION RATES",IF('入力 Inputs'!$F$1="日本語","年金コミッション率","年金コミッション率 / ANNUITY COMMISSION RATES")) -> ANNUITY COMMISSION RATES
A35: =IF('入力 Inputs'!$F$1="English","Product",IF('入力 Inputs'!$F$1="日本語","商品","商品 / Product")) -> Product | B35: =IF('入力 Inputs'!$F$1="English","OGA %",IF('入力 Inputs'!$F$1="日本語","OGA率","OGA率 / OGA %")) -> OGA % | C35: =IF('入力 Inputs'!$F$1="English","Processor (95%) %",IF('入力 Inputs'!$F$1="日本語","プロセッサー率","プロセッサー率 / Processor (95%) %")) -> Processor (95%) % | D35: =IF('入力 Inputs'!$F$1="English","Regional %",IF('入力 Inputs'!$F$1="日本語","リージョナル率","リージョナル率 / Regional %")) -> Regional % | E35: =IF('入力 Inputs'!$F$1="English","Notes",IF('入力 Inputs'!$F$1="日本語","備考","備考 / Notes")) -> Notes
A36: =IF('入力 Inputs'!$F$1="English","Intl Fixed Rate Plan Plus",IF('入力 Inputs'!$F$1="日本語","国際固定金利プランプラス","国際固定金利プランプラス / Intl Fixed Rate Plan Plus")) -> Intl Fixed Rate Plan Plus | B36: 0.05 | C36: 0.0475 | D36: 0.045
A37: =IF('入力 Inputs'!$F$1="English","Intl Fixed Rate Plan",IF('入力 Inputs'!$F$1="日本語","国際固定金利プラン","国際固定金利プラン / Intl Fixed Rate Plan")) -> Intl Fixed Rate Plan | B37: 0.043 | C37: 0.04085 | D37: 0.0387
A38: =IF('入力 Inputs'!$F$1="English","US 5-Year FIA (AmFirst / Trailhead)",IF('入力 Inputs'!$F$1="日本語","米国5年FIA","米国5年FIA / US 5-Year FIA (AmFirst / Trailhead)")) -> US 5-Year FIA (AmFirst / Trailhead) | B38: 0.0775 | C38: =B38*0.95 -> 0.073625 | D38: 0.045 | E38: No Processor tier in Axonic schedule. Regional = 4.5% per Axonic grid.
A40: =IF('入力 Inputs'!$F$1="English","ANNUAL FUND CHARGES (Step 4)",IF('入力 Inputs'!$F$1="日本語","年間ファンド手数料（ステップ4）","年間ファンド手数料（ステップ4） / ANNUAL FUND CHARGES (Step 4)")) -> ANNUAL FUND CHARGES (Step 4)
A41: =IF('入力 Inputs'!$F$1="English","Advantage M&E %",IF('入力 Inputs'!$F$1="日本語","Advantage M&E率","Advantage M&E率 / Advantage M&E %")) -> Advantage M&E % | B41: 0.0015
A42: =IF('入力 Inputs'!$F$1="English","Syndicated / Stephen RIA %",IF('入力 Inputs'!$F$1="日本語","シンジケート/Stephen RIA率","シンジケート/Stephen RIA率 / Syndicated / Stephen RIA %")) -> Syndicated / Stephen RIA % | B42: 0.0015
A43: =IF('入力 Inputs'!$F$1="English","Inspira custodian %",IF('入力 Inputs'!$F$1="日本語","インスピラ保管料率","インスピラ保管料率 / Inspira custodian %")) -> Inspira custodian % | B43: 0.0005 | E43: Updated per Inspira fee schedule
A44: =IF('入力 Inputs'!$F$1="English","Money Manager fee %",IF('入力 Inputs'!$F$1="日本語","マネーマネージャー手数料率","マネーマネージャー手数料率 / Money Manager fee %")) -> Money Manager fee % | B44: 0 | E44: Default 0% — set rate when money manager is engaged
A45: =IF('入力 Inputs'!$F$1="English","Est. Year 1 actual fees",IF('入力 Inputs'!$F$1="日本語","推定初年度実費","推定初年度実費 / Est. Year 1 actual fees")) -> Est. Year 1 actual fees | B45: 26000 | E45: ← adjust when confirmed (incl. Q1)
A47: =IF('入力 Inputs'!$F$1="English","GROWTH ASSUMPTIONS (Step 5)",IF('入力 Inputs'!$F$1="日本語","成長仮定（ステップ5）","成長仮定（ステップ5） / GROWTH ASSUMPTIONS (Step 5)")) -> GROWTH ASSUMPTIONS (Step 5)
...

Sheet 計算 Calculations
A1: =IF('入力 Inputs'!$F$1="English","PPVA DEAL MODEL — FULL CALCULATION DETAIL",IF('入力 Inputs'!$F$1="日本語","PPVA取引モデル — 計算詳細","PPVA取引モデル — 計算詳細 / PPVA DEAL MODEL — FULL CALCULATION DETAIL")) -> PPVA DEAL MODEL — FULL CALCULATION DETAIL
A2: =IF('入力 Inputs'!$F$1="English","All values pull from Inputs sheet. Update inputs there.",IF('入力 Inputs'!$F$1="日本語","全ての値は入力シートから取得。入力を変更すると自動再計算","全ての値は入力シートから取得。入力を変更すると自動再計算 / All values pull from Inputs sheet. Update inputs there.")) -> All values pull from Inputs sheet. Update inputs there.
A4: =IF('入力 Inputs'!$F$1="English","STEP 1 — PREMIUM LOAD",IF('入力 Inputs'!$F$1="日本語","ステップ1 — プレミアムロード","ステップ1 — プレミアムロード / STEP 1 — PREMIUM LOAD")) -> STEP 1 — PREMIUM LOAD
A5: =IF('入力 Inputs'!$F$1="English","Total Deposit",IF('入力 Inputs'!$F$1="日本語","預入総額","預入総額 / Total Deposit")) -> Total Deposit | B5: ='入力 Inputs'!B7 -> 13000000
A6: =IF('入力 Inputs'!$F$1="English","Premium Load (6%)",IF('入力 Inputs'!$F$1="日本語","プレミアムロード（6%）","プレミアムロード（6%） / Premium Load (6%)")) -> Premium Load (6%) | B6: ='入力 Inputs'!B7*'入力 Inputs'!B11 -> 780000 | C6: ='入力 Inputs'!B11 -> 0.06
A7: =IF('入力 Inputs'!$F$1="English","3cStructures (1%)",IF('入力 Inputs'!$F$1="日本語","3cStructures（1%）","3cStructures（1%） / 3cStructures (1%)")) -> 3cStructures (1%) | B7: ='入力 Inputs'!B7*'入力 Inputs'!B12 -> 130000 | C7: ='入力 Inputs'!B12 -> 0.01
A8: =IF('入力 Inputs'!$F$1="English","Total Premium Load",IF('入力 Inputs'!$F$1="日本語","プレミアムロード合計","プレミアムロード合計 / Total Premium Load")) -> Total Premium Load | B8: =B6+B7 -> 910000 | C8: ='入力 Inputs'!B11+'入力 Inputs'!B12 -> 0.07
A10: =IF('入力 Inputs'!$F$1="English","Premium Load Payout Waterfall",IF('入力 Inputs'!$F$1="日本語","プレミアムロード支払ウォーターフォール","プレミアムロード支払ウォーターフォール / Premium Load Payout Waterfall")) -> Premium Load Payout Waterfall
A11: =IF('入力 Inputs'!$F$1="English","Syndicated Capital Holdback (0.05 × 6%)",IF('入力 Inputs'!$F$1="日本語","Syndicated Capital保持（0.05 × 6%）","Syndicated Capital保持（0.05 × 6%） / Syndicated Capital Holdback (0.05 × 6%)")) -> Syndicated Capital Holdback (0.05 × 6%) | B11: =B6*'入力 Inputs'!B13 -> 39000 | C11: ='入力 Inputs'!B13 -> 0.05 | E11: Syndicated Capital retains 5% of premium load
A12: =IF('入力 Inputs'!$F$1="English","Net to Stephen (Syndicated)",IF('入力 Inputs'!$F$1="日本語","Stephenへのネット（Syndicated）","Stephenへのネット（Syndicated） / Net to Stephen (Syndicated)")) -> Net to Stephen (Syndicated) | B12: =B6-B11 -> 741000 | E12: Sweeps from Stephen to PB Investment Services
A13: =IF('入力 Inputs'!$F$1="English","PB Investment Services Holdback (0.05 × 6%)",IF('入力 Inputs'!$F$1="日本語","PB Investment Services保持（0.05 × 6%）","PB Investment Services保持（0.05 × 6%） / PB Investment Services Holdback (0.05 × 6%)")) -> PB Investment Services Holdback (0.05 × 6%) | B13: =B6*'入力 Inputs'!B14 -> 39000 | C13: ='入力 Inputs'!B14 -> 0.05 | E13: PB Investment Services retains 5% of premium load
A14: =IF('入力 Inputs'!$F$1="English","PB sends to PBWR (5.4%)",IF('入力 Inputs'!$F$1="日本語","PBからPBWRへ送金（5.4%）","PBからPBWRへ送金（5.4%） / PB sends to PBWR (5.4%)")) -> PB sends to PBWR (5.4%) | B14: =B12-B13 -> 702000 | C14: =B14/'入力 Inputs'!B7 -> 0.054 | E14: Effective rate 5.4% of deposit
A15: =IF('入力 Inputs'!$F$1="English"," PBWR share (50%)",IF('入力 Inputs'!$F$1="日本語"," PBWR分配（50%）"," PBWR分配（50%） / PBWR share (50%)")) -> PBWR share (50%) | B15: =B14*'入力 Inputs'!B15 -> 351000 | C15: ='入力 Inputs'!B15 -> 0.5 | E15: ← verify per Ohana contract
A16: =IF('入力 Inputs'!$F$1="English"," Ohana share (50%)",IF('入力 Inputs'!$F$1="日本語"," Ohana分配（50%）"," Ohana分配（50%） / Ohana share (50%)")) -> Ohana share (50%) | B16: =B14*'入力 Inputs'!B16 -> 351000 | C16: ='入力 Inputs'!B16 -> 0.5 | E16: ← verify per Ohana contract
A18: =IF('入力 Inputs'!$F$1="English","STEP 2 — ADMIN & BANK FEES",IF('入力 Inputs'!$F$1="日本語","ステップ2 — 管理・銀行手数料","ステップ2 — 管理・銀行手数料 / STEP 2 — ADMIN & BANK FEES")) -> STEP 2 — ADMIN & BANK FEES
A19: =IF('入力 Inputs'!$F$1="English","Advantage annuity admin fee",IF('入力 Inputs'!$F$1="日本語","Advantage年金管理費","Advantage年金管理費 / Advantage annuity admin fee")) -> Advantage annuity admin fee | B19: ='入力 Inputs'!B19 -> 19500 | D19: Source: Sam Jensen email ( verify where this is being paid)
A20: =IF('入力 Inputs'!$F$1="English","Misc. bank / setup fees",IF('入力 Inputs'!$F$1="日本語","その他銀行・設定費","その他銀行・設定費 / Misc. bank / setup fees")) -> Misc. bank / setup fees | B20: ='入力 Inputs'!B20 -> 1500 | D20: Source: Sam Jensen email — Confirm total figure
A21: =IF('入力 Inputs'!$F$1="English","Total Admin & Fees",IF('入力 Inputs'!$F$1="日本語","管理手数料合計","管理手数料合計 / Total Admin & Fees")) -> Total Admin & Fees | B21: =B19+B20 -> 21000
A23: =IF('入力 Inputs'!$F$1="English","NET WIRED TO INSPIRA",IF('入力 Inputs'!$F$1="日本語","インスピラへの正味送金額","インスピラへの正味送金額 / NET WIRED TO INSPIRA")) -> NET WIRED TO INSPIRA | B23: ='入力 Inputs'!B7-B8-B21 -> 12069000
A25: =IF('入力 Inputs'!$F$1="English","STEP 3 — INSPIRA FUND ALLOCATIONS",IF('入力 Inputs'!$F$1="日本語","ステップ3 — インスピラファンド配分","ステップ3 — インスピラファンド配分 / STEP 3 — INSPIRA FUND ALLOCATIONS")) -> STEP 3 — INSPIRA FUND ALLOCATIONS
A26: =IF('入力 Inputs'!$F$1="English","Product",IF('入力 Inputs'!$F$1="日本語","商品","商品 / Product")) -> Product | B26: Alloc % | C26: Amount | D26: Est. Rate | E26: Wtd Return | F26: OGA Comm | H26: Proc Comm | I26: Reg Comm
A27: =IF('入力 Inputs'!$F$1="English","GUARANTEED PRODUCTS (75%)",IF('入力 Inputs'!$F$1="日本語","保証商品（75%）","保証商品（75%） / GUARANTEED PRODUCTS (75%)")) -> GUARANTEED PRODUCTS (75%)
A28: =IF('入力 Inputs'!$F$1="English","Intl Fixed Rate Plan Plus",IF('入力 Inputs'!$F$1="日本語","国際固定金利プランプラス","国際固定金利プランプラス / Intl Fixed Rate Plan Plus")) -> Intl Fixed Rate Plan Plus | B28: ='入力 Inputs'!B25 -> 0.35 | C28: ='入力 Inputs'!C25 -> 4224150 | D28: ='入力 Inputs'!D25 -> 0.058 | E28: =B28*D28 -> 0.0203 | F28: ='入力 Inputs'!C25*'入力 Inputs'!B36 -> 211207.5 | H28: ='入力 Inputs'!C25*'入力 Inputs'!C36 -> 200647.12 | I28: ='入力 Inputs'!C25*'入力 Inputs'!D36 -> 190086.75
A29: =IF('入力 Inputs'!$F$1="English","Intl Fixed Rate Plan",IF('入力 Inputs'!$F$1="日本語","国際固定金利プラン","国際固定金利プラン / Intl Fixed Rate Plan")) -> Intl Fixed Rate Plan | B29: ='入力 Inputs'!B26 -> 0.25 | C29: ='入力 Inputs'!C26 -> 3017250 | D29: ='入力 Inputs'!D26 -> 0.056 | E29: =B29*D29 -> 0.014 | F29: ='入力 Inputs'!C26*'入力 Inputs'!B37 -> 129741.75 | H29: ='入力 Inputs'!C26*'入力 Inputs'!C37 -> 123254.66 | I29: ='入力 Inputs'!C26*'入力 Inputs'!D37 -> 116767.57
A30: =IF('入力 Inputs'!$F$1="English","US 5-Year FIA (AmFirst / Trailhead)",IF('入力 Inputs'!$F$1="日本語","米国5年FIA","米国5年FIA / US 5-Year FIA (AmFirst / Trailhead)")) -> US 5-Year FIA (AmFirst / Trailhead) | B30: ='入力 Inputs'!B27 -> 0.15 | C30: ='入力 Inputs'!C27 -> 1810350 | D30: ='入力 Inputs'!D27 -> 0.0515 | E30: =B30*D30 -> 0.007725 | F30: ='入力 Inputs'!C27*'入力 Inputs'!B38 -> 140302.12 | H30: ='入力 Inputs'!C38*C30 -> 133287.02 | I30: ='入力 Inputs'!C27*'入力 Inputs'!D38 -> 81465.75
A31: =IF('入力 Inputs'!$F$1="English","Guaranteed Subtotal (75%)",IF('入力 Inputs'!$F$1="日本語","保証商品小計（75%）","保証商品小計（75%） / Guaranteed Subtotal (75%)")) -> Guaranteed Subtotal (75%) | B31: =B28+B29+B30 -> 0.75 | C31: =C28+C29+C30 -> 9051750 | E31: =E28+E29+E30 -> 0.042025 | F31: =F28+F29+F30 -> 481251.38 | H31: =H28+H29+H30 -> 457188.81 | I31: =I28+I29+I30 -> 388320.08
A33: =IF('入力 Inputs'!$F$1="English","NON-GUARANTEED (25%)",IF('入力 Inputs'!$F$1="日本語","非保証（25%）","非保証（25%） / NON-GUARANTEED (25%)")) -> NON-GUARANTEED (25%)
A34: =IF('入力 Inputs'!$F$1="English","AAIDX (Alt Income — Investment Fund)",IF('入力 Inputs'!$F$1="日本語","AAIDX（代替収益）","AAIDX（代替収益） / AAIDX (Alt Income — Investment Fund)")) -> AAIDX (Alt Income — Investment Fund) | B34: ='入力 Inputs'!B29 -> 0.1 | C34: ='入力 Inputs'!C29 -> 1206900 | D34: ='入力 Inputs'!D29 -> 0.07 | E34: =B34*D34 -> 0.007 | F34: — | H34: — | I34: —
A35: =IF('入力 Inputs'!$F$1="English","ACRE III (CRE Fund — Investment Fund)",IF('入力 Inputs'!$F$1="日本語","ACRE III（CREファンド）","ACRE III（CREファンド） / ACRE III (CRE Fund — Investment Fund)")) -> ACRE III (CRE Fund — Investment Fund) | B35: ='入力 Inputs'!B30 -> 0.1 | C35: ='入力 Inputs'!C30 -> 1206900 | D35: ='入力 Inputs'!D30 -> 0.12 | E35: =B35*D35 -> 0.012 | F35: — | H35: — | I35: —
A36: =IF('入力 Inputs'!$F$1="English","Cash (Liquidity)",IF('入力 Inputs'!$F$1="日本語","現金（流動性）","現金（流動性） / Cash (Liquidity)")) -> Cash (Liquidity) | B36: ='入力 Inputs'!B31 -> 0.05 | C36: ='入力 Inputs'!C31 -> 603450 | D36: ='入力 Inputs'!D31 -> 0.03 | E36: =B36*D36 -> 0.0015 | F36: — | H36: — | I36: —
A37: =IF('入力 Inputs'!$F$1="English","Non-Guaranteed Subtotal (25%)",IF('入力 Inputs'!$F$1="日本語","非保証商品小計（25%）","非保証商品小計（25%） / Non-Guaranteed Subtotal (25%)")) -> Non-Guaranteed Subtotal (25%) | B37: =B34+B35+B36 -> 0.25 | C37: =C34+C35+C36 -> 3017250 | E37: =E34+E35+E36 -> 0.0205 | F37: — | H37: — | I37: —
A39: =IF('入力 Inputs'!$F$1="English","TOTAL ALLOCATION",IF('入力 Inputs'!$F$1="日本語","配分合計","配分合計 / TOTAL ALLOCATION")) -> TOTAL ALLOCATION | B39: =B31+B37 -> 1 | C39: =C31+C37 -> 12069000 | E39: =E31+E37 -> 0.062525 | F39: =F31 -> 481251.38 | H39: =H31 -> 457188.81 | I39: =I31 -> 388320.08
A40: Commission applies to annuity products only. Investment funds (AAIDX, ACRE III, Cash) carry no commission.
A42: Marketing allowance = equivalent of Axonic regular commission on annuity premiums. Verify OGA vs. Processor vs. Regional rate level per contract language.
A44: =IF('入力 Inputs'!$F$1="English","STEP 4 — ONGOING ANNUAL FUND CHARGES",IF('入力 Inputs'!$F$1="日本語","ステップ4 — 年間ファンド手数料","ステップ4 — 年間ファンド手数料 / STEP 4 — ONGOING ANNUAL FUND CHARGES")) -> STEP 4 — ONGOING ANNUAL FUND CHARGES
A45: =IF('入力 Inputs'!$F$1="English","Fee Recipient",IF('入力 Inputs'!$F$1="日本語","手数料受取者","手数料受取者 / Fee Recipient")) -> Fee Recipient | B45: Rate | D45: Est. Annual $ on Net
A46: =IF('入力 Inputs'!$F$1="English","Advantage (M&E)",IF('入力 Inputs'!$F$1="日本語","Advantage（M&E）","Advantage（M&E） / Advantage (M&E)")) -> Advantage (M&E) | B46: ='入力 Inputs'!B41 -> 0.0015 | D46: =B23*'入力 Inputs'!B41 -> 18103.5
A47: =IF('入力 Inputs'!$F$1="English","Stephen / Syndicated (Investment Advisor)",IF('入力 Inputs'!$F$1="日本語","Stephen / シンジケート（投資アドバイザー）","Stephen / シンジケート（投資アドバイザー） / Stephen / Syndicated (Investment Advisor)")) -> Stephen / Syndicated (Investment Advisor) | B47: ='入力 Inputs'!B42 -> 0.0015 | D47: =B23*'入力 Inputs'!B42 -> 18103.5
A48: =IF('入力 Inputs'!$F$1="English","Inspira (Custodian 0.05%)",IF('入力 Inputs'!$F$1="日本語","インスピラ（保管料0.05%）","インスピラ（保管料0.05%） / Inspira (Custodian 0.05%)")) -> Inspira (Custodian 0.05%) | B48: ='入力 Inputs'!B43 -> 0.0005 | D48: =B23*'入力 Inputs'!B43 -> 6034.5
A49: =IF('入力 Inputs'!$F$1="English","Money Manager",IF('入力 Inputs'!$F$1="日本語","マネーマネージャー","マネーマネージャー / Money Manager")) -> Money Manager | B49: ='入力 Inputs'!B44 -> 0 | D49: =B23*'入力 Inputs'!B44 -> 0
...

Sheet キャリア Carrier Illust.
A1: =IF('入力 Inputs'!$F$1="English","PPVA CARRIER ILLUSTRATION",IF('入力 Inputs'!$F$1="日本語","PPVAキャリアイラストレーション","PPVAキャリアイラストレーション / PPVA CARRIER ILLUSTRATION")) -> PPVA CARRIER ILLUSTRATION
A2: =IF('入力 Inputs'!$F$1="English","All values pull from Inputs. Fund value at 3 illustrated rates.",IF('入力 Inputs'!$F$1="日本語","全ての値は入力シートから取得。3つの例示率でファンド価値を表示","全ての値は入力シートから取得。3つの例示率でファンド価値を表示 / All values pull from Inputs. Fund value at 3 illustrated rates.")) -> All values pull from Inputs. Fund value at 3 illustrated rates.
A4: =IF('入力 Inputs'!$F$1="English","Year",IF('入力 Inputs'!$F$1="日本語","年","年 / Year")) -> Year | B4: =IF('入力 Inputs'!$F$1="English","Age",IF('入力 Inputs'!$F$1="日本語","年齢","年齢 / Age")) -> Age | C4: =IF('入力 Inputs'!$F$1="English","Net Deposit",IF('入力 Inputs'!$F$1="日本語","正味預入額","正味預入額 / Net Deposit")) -> Net Deposit | D4: =IF('入力 Inputs'!$F$1="English","Fund Value ("&TEXT('入力 Inputs'!B83,"0.0%")&")",IF('入力 Inputs'!$F$1="日本語","ファンド価値（"&TEXT('入力 Inputs'!B83,"0.0%")&"）","ファンド価値 / Fund Value ("&TEXT('入力 Inputs'!B83,"0.0%")&")")) -> Fund Value (6.3%) | E4: =IF('入力 Inputs'!$F$1="English","Surrender Value ("&TEXT('入力 Inputs'!B83,"0.0%")&")",IF('入力 Inputs'!$F$1="日本語","解約返戻金（"&TEXT('入力 Inputs'!B83,"0.0%")&"）","解約返戻金 / Surrender Value ("&TEXT('入力 Inputs'!B83,"0.0%")&")")) -> Surrender Value (6.3%) | F4: =IF('入力 Inputs'!$F$1="English","Death Benefit ("&TEXT('入力 Inputs'!B83,"0.0%")&")",IF('入力 Inputs'!$F$1="日本語","死亡保険金（"&TEXT('入力 Inputs'!B83,"0.0%")&"）","死亡保険金 / Death Benefit ("&TEXT('入力 Inputs'!B83,"0.0%")&")")) -> Death Benefit (6.3%) | G4: =IF('入力 Inputs'!$F$1="English","Fund Value ("&TEXT('入力 Inputs'!B84,"0.0%")&")",IF('入力 Inputs'!$F$1="日本語","ファンド価値（"&TEXT('入力 Inputs'!B84,"0.0%")&"）","ファンド価値 / Fund Value ("&TEXT('入力 Inputs'!B84,"0.0%")&")")) -> Fund Value (6.5%) | H4: =IF('入力 Inputs'!$F$1="English","Surrender Value ("&TEXT('入力 Inputs'!B84,"0.0%")&")",IF('入力 Inputs'!$F$1="日本語","解約返戻金（"&TEXT('入力 Inputs'!B84,"0.0%")&"）","解約返戻金 / Surrender Value ("&TEXT('入力 Inputs'!B84,"0.0%")&")")) -> Surrender Value (6.5%) | I4: =IF('入力 Inputs'!$F$1="English","Death Benefit ("&TEXT('入力 Inputs'!B84,"0.0%")&")",IF('入力 Inputs'!$F$1="日本語","死亡保険金（"&TEXT('入力 Inputs'!B84,"0.0%")&"）","死亡保険金 / Death Benefit ("&TEXT('入力 Inputs'!B84,"0.0%")&")")) -> Death Benefit (6.5%) | J4: =IF('入力 Inputs'!$F$1="English","Fund Value ("&TEXT('入力 Inputs'!B85,"0.0%")&")",IF('入力 Inputs'!$F$1="日本語","ファンド価値（"&TEXT('入力 Inputs'!B85,"0.0%")&"）","ファンド価値 / Fund Value ("&TEXT('入力 Inputs'!B85,"0.0%")&")")) -> Fund Value (7.0%) | K4: =IF('入力 Inputs'!$F$1="English","Surrender Value ("&TEXT('入力 Inputs'!B85,"0.0%")&")",IF('入力 Inputs'!$F$1="日本語","解約返戻金（"&TEXT('入力 Inputs'!B85,"0.0%")&"）","解約返戻金 / Surrender Value ("&TEXT('入力 Inputs'!B85,"0.0%")&")")) -> Surrender Value (7.0%) | L4: =IF('入力 Inputs'!$F$1="English","Death Benefit ("&TEXT('入力 Inputs'!B85,"0.0%")&")",IF('入力 Inputs'!$F$1="日本語","死亡保険金（"&TEXT('入力 Inputs'!B85,"0.0%")&"）","死亡保険金 / Death Benefit ("&TEXT('入力 Inputs'!B85,"0.0%")&")")) -> Death Benefit (7.0%) | M4: =IF('入力 Inputs'!$F$1="English","Fund Value JPY (Base)",IF('入力 Inputs'!$F$1="日本語","ファンド価値・円（基準）","ファンド価値・円（基準） / Fund Value JPY (Base)")) -> Fund Value JPY (Base) | N4: Year | O4: ="Base ("&TEXT('入力 Inputs'!B83,"0.0%")&")" -> Base (6.3%) | P4: ="Alt 1 ("&TEXT('入力 Inputs'!B84,"0.0%")&")" -> Alt 1 (6.5%) | Q4: ="Alt 2 ("&TEXT('入力 Inputs'!B85,"0.0%")&")" -> Alt 2 (7.0%)
A5: =IF(1<='入力 Inputs'!$B$86,1,"") -> 1 | B5: =IF(A5="","",'入力 Inputs'!$B$55+A5) -> 47 | C5: =IF(A5="","",'入力 Inputs'!B7) -> 13000000 | D5: =IF(A5="","",('入力 Inputs'!B87-'入力 Inputs'!B87*'入力 Inputs'!B41-'入力 Inputs'!B57)*(1+'入力 Inputs'!B83)) -> 12826532 | E5: {=IF(A5="","",IF(A5<=10,D5*(1-INDEX('入力 Inputs'!$B$71:$B$80,A5)),D5))} -> 641326.62 | F5: =IF(A5="","",D5) -> 12826532 | G5: =IF(A5="","",('入力 Inputs'!B87-'入力 Inputs'!B87*'入力 Inputs'!B41-'入力 Inputs'!B57)*(1+'入力 Inputs'!B84)) -> 12856410 | H5: {=IF(A5="","",IF(A5<=10,G5*(1-INDEX('入力 Inputs'!$B$71:$B$80,A5)),G5))} -> 642820.5 | I5: =IF(A5="","",G5) -> 12856410 | J5: =IF(A5="","",('入力 Inputs'!B87-'入力 Inputs'!B87*'入力 Inputs'!B41-'入力 Inputs'!B57)*(1+'入力 Inputs'!B85)) -> 12916769 | K5: {=IF(A5="","",IF(A5<=10,J5*(1-INDEX('入力 Inputs'!$B$71:$B$80,A5)),J5))} -> 645838.43 | L5: =IF(A5="","",J5) -> 12916769 | M5: =IF(A5="","",D5*'入力 Inputs'!$B$64) -> 2.0522452e+09 | N5: =A5 -> 1 | O5: =IF(A5="","",D5) -> 12826532 | P5: =IF(A5="","",G5) -> 12856410 | Q5: =IF(A5="","",J5) -> 12916769
A6: =IF(2<='入力 Inputs'!$B$86,2,"") -> 2 | B6: =IF(A6="","",'入力 Inputs'!$B$55+A6) -> 48 | C6: =IF(A6="","",0) -> 0 | D6: =IF(A6="","",(D5-D5*'入力 Inputs'!$B$41-'入力 Inputs'!$B$57*(1+'入力 Inputs'!$B$91)^(2-1))*(1+'入力 Inputs'!$B$83)) -> 13607939 | E6: {=IF(A6="","",IF(A6<=10,D6*(1-INDEX('入力 Inputs'!$B$71:$B$80,A6)),D6))} -> 1360793.9 | F6: =IF(A6="","",D6) -> 13607939 | G6: =IF(A6="","",(G5-G5*'入力 Inputs'!$B$41-'入力 Inputs'!$B$57*(1+'入力 Inputs'!$B$91)^(2-1))*(1+'入力 Inputs'!$B$84)) -> 13671408 | H6: {=IF(A6="","",IF(A6<=10,G6*(1-INDEX('入力 Inputs'!$B$71:$B$80,A6)),G6))} -> 1367140.8 | I6: =IF(A6="","",G6) -> 13671408 | J6: =IF(A6="","",(J5-J5*'入力 Inputs'!$B$41-'入力 Inputs'!$B$57*(1+'入力 Inputs'!$B$91)^(2-1))*(1+'入力 Inputs'!$B$85)) -> 13800080 | K6: {=IF(A6="","",IF(A6<=10,J6*(1-INDEX('入力 Inputs'!$B$71:$B$80,A6)),J6))} -> 1380008 | L6: =IF(A6="","",J6) -> 13800080 | M6: =IF(A6="","",D6*'入力 Inputs'!$B$64) -> 2.1772702e+09 | N6: =A6 -> 2 | O6: =IF(A6="","",D6) -> 13607939 | P6: =IF(A6="","",G6) -> 13671408 | Q6: =IF(A6="","",J6) -> 13800080
A7: =IF(3<='入力 Inputs'!$B$86,3,"") -> 3 | B7: =IF(A7="","",'入力 Inputs'!$B$55+A7) -> 49 | C7: =IF(A7="","",0) -> 0 | D7: =IF(A7="","",(D6-D6*'入力 Inputs'!$B$41-'入力 Inputs'!$B$57*(1+'入力 Inputs'!$B$91)^(3-1))*(1+'入力 Inputs'!$B$83)) -> 14436953 | E7: {=IF(A7="","",IF(A7<=10,D7*(1-INDEX('入力 Inputs'!$B$71:$B$80,A7)),D7))} -> 2887390.7 | F7: =IF(A7="","",D7) -> 14436953 | G7: =IF(A7="","",(G6-G6*'入力 Inputs'!$B$41-'入力 Inputs'!$B$57*(1+'入力 Inputs'!$B$91)^(3-1))*(1+'入力 Inputs'!$B$84)) -> 14538076 | H7: {=IF(A7="","",IF(A7<=10,G7*(1-INDEX('入力 Inputs'!$B$71:$B$80,A7)),G7))} -> 2907615.2 | I7: =IF(A7="","",G7) -> 14538076 | J7: =IF(A7="","",(J6-J6*'入力 Inputs'!$B$41-'入力 Inputs'!$B$57*(1+'入力 Inputs'!$B$91)^(3-1))*(1+'入力 Inputs'!$B$85)) -> 14743802 | K7: {=IF(A7="","",IF(A7<=10,J7*(1-INDEX('入力 Inputs'!$B$71:$B$80,A7)),J7))} -> 2948760.5 | L7: =IF(A7="","",J7) -> 14743802 | M7: =IF(A7="","",D7*'入力 Inputs'!$B$64) -> 2.3099125e+09 | N7: =A7 -> 3 | O7: =IF(A7="","",D7) -> 14436953 | P7: =IF(A7="","",G7) -> 14538076 | Q7: =IF(A7="","",J7) -> 14743802
A8: =IF(4<='入力 Inputs'!$B$86,4,"") -> 4 | B8: =IF(A8="","",'入力 Inputs'!$B$55+A8) -> 50 | C8: =IF(A8="","",0) -> 0 | D8: =IF(A8="","",(D7-D7*'入力 Inputs'!$B$41-'入力 Inputs'!$B$57*(1+'入力 Inputs'!$B$91)^(4-1))*(1+'入力 Inputs'!$B$83)) -> 15316477 | E8: {=IF(A8="","",IF(A8<=10,D8*(1-INDEX('入力 Inputs'!$B$71:$B$80,A8)),D8))} -> 4594943 | F8: =IF(A8="","",D8) -> 15316477 | G8: =IF(A8="","",(G7-G7*'入力 Inputs'!$B$41-'入力 Inputs'!$B$57*(1+'入力 Inputs'!$B$91)^(4-1))*(1+'入力 Inputs'!$B$84)) -> 15459688 | H8: {=IF(A8="","",IF(A8<=10,G8*(1-INDEX('入力 Inputs'!$B$71:$B$80,A8)),G8))} -> 4637906.5 | I8: =IF(A8="","",G8) -> 15459688 | J8: =IF(A8="","",(J7-J7*'入力 Inputs'!$B$41-'入力 Inputs'!$B$57*(1+'入力 Inputs'!$B$91)^(4-1))*(1+'入力 Inputs'!$B$85)) -> 15752066 | K8: {=IF(A8="","",IF(A8<=10,J8*(1-INDEX('入力 Inputs'!$B$71:$B$80,A8)),J8))} -> 4725619.8 | L8: =IF(A8="","",J8) -> 15752066 | M8: =IF(A8="","",D8*'入力 Inputs'!$B$64) -> 2.4506363e+09 | N8: =A8 -> 4 | O8: =IF(A8="","",D8) -> 15316477 | P8: =IF(A8="","",G8) -> 15459688 | Q8: =IF(A8="","",J8) -> 15752066
A9: =IF(5<='入力 Inputs'!$B$86,5,"") -> 5 | B9: =IF(A9="","",'入力 Inputs'!$B$55+A9) -> 51 | C9: =IF(A9="","",0) -> 0 | D9: =IF(A9="","",(D8-D8*'入力 Inputs'!$B$41-'入力 Inputs'!$B$57*(1+'入力 Inputs'!$B$91)^(5-1))*(1+'入力 Inputs'!$B$83)) -> 16249586 | E9: {=IF(A9="","",IF(A9<=10,D9*(1-INDEX('入力 Inputs'!$B$71:$B$80,A9)),D9))} -> 6499834.6 | F9: =IF(A9="","",D9) -> 16249586 | G9: =IF(A9="","",(G8-G8*'入力 Inputs'!$B$41-'入力 Inputs'!$B$57*(1+'入力 Inputs'!$B$91)^(5-1))*(1+'入力 Inputs'!$B$84)) -> 16439729 | H9: {=IF(A9="","",IF(A9<=10,G9*(1-INDEX('入力 Inputs'!$B$71:$B$80,A9)),G9))} -> 6575891.6 | I9: =IF(A9="","",G9) -> 16439729 | J9: =IF(A9="","",(J8-J8*'入力 Inputs'!$B$41-'入力 Inputs'!$B$57*(1+'入力 Inputs'!$B$91)^(5-1))*(1+'入力 Inputs'!$B$85)) -> 16829286 | K9: {=IF(A9="","",IF(A9<=10,J9*(1-INDEX('入力 Inputs'!$B$71:$B$80,A9)),J9))} -> 6731714.3 | L9: =IF(A9="","",J9) -> 16829286 | M9: =IF(A9="","",D9*'入力 Inputs'!$B$64) -> 2.5999338e+09 | N9: =A9 -> 5 | O9: =IF(A9="","",D9) -> 16249586 | P9: =IF(A9="","",G9) -> 16439729 | Q9: =IF(A9="","",J9) -> 16829286
A10: =IF(6<='入力 Inputs'!$B$86,6,"") -> 6 | B10: =IF(A10="","",'入力 Inputs'!$B$55+A10) -> 52 | C10: =IF(A10="","",0) -> 0 | D10: =IF(A10="","",(D9-D9*'入力 Inputs'!$B$41-'入力 Inputs'!$B$57*(1+'入力 Inputs'!$B$91)^(6-1))*(1+'入力 Inputs'!$B$83)) -> 17239547 | E10: {=IF(A10="","",IF(A10<=10,D10*(1-INDEX('入力 Inputs'!$B$71:$B$80,A10)),D10))} -> 17239547 | F10: =IF(A10="","",D10) -> 17239547 | G10: =IF(A10="","",(G9-G9*'入力 Inputs'!$B$41-'入力 Inputs'!$B$57*(1+'入力 Inputs'!$B$91)^(6-1))*(1+'入力 Inputs'!$B$84)) -> 17481903 | H10: {=IF(A10="","",IF(A10<=10,G10*(1-INDEX('入力 Inputs'!$B$71:$B$80,A10)),G10))} -> 17481903 | I10: =IF(A10="","",G10) -> 17481903 | J10: =IF(A10="","",(J9-J9*'入力 Inputs'!$B$41-'入力 Inputs'!$B$57*(1+'入力 Inputs'!$B$91)^(6-1))*(1+'入力 Inputs'!$B$85)) -> 17980178 | K10: {=IF(A10="","",IF(A10<=10,J10*(1-INDEX('入力 Inputs'!$B$71:$B$80,A10)),J10))} -> 17980178 | L10: =IF(A10="","",J10) -> 17980178 | M10: =IF(A10="","",D10*'入力 Inputs'!$B$64) -> 2.7583276e+09 | N10: =A10 -> 6 | O10: =IF(A10="","",D10) -> 17239547 | P10: =IF(A10="","",G10) -> 17481903 | Q10: =IF(A10="","",J10) -> 17980178
A11: =IF(7<='入力 Inputs'!$B$86,7,"") -> 7 | B11: =IF(A11="","",'入力 Inputs'!$B$55+A11) -> 53 | C11: =IF(A11="","",0) -> 0 | D11: =IF(A11="","",(D10-D10*'入力 Inputs'!$B$41-'入力 Inputs'!$B$57*(1+'入力 Inputs'!$B$91)^(7-1))*(1+'入力 Inputs'!$B$83)) -> 18289823 | E11: {=IF(A11="","",IF(A11<=10,D11*(1-INDEX('入力 Inputs'!$B$71:$B$80,A11)),D11))} -> 18289823 | F11: =IF(A11="","",D11) -> 18289823 | G11: =IF(A11="","",(G10-G10*'入力 Inputs'!$B$41-'入力 Inputs'!$B$57*(1+'入力 Inputs'!$B$91)^(7-1))*(1+'入力 Inputs'!$B$84)) -> 18590148 | H11: {=IF(A11="","",IF(A11<=10,G11*(1-INDEX('入力 Inputs'!$B$71:$B$80,A11)),G11))} -> 18590148 | I11: =IF(A11="","",G11) -> 18590148 | J11: =IF(A11="","",(J10-J10*'入力 Inputs'!$B$41-'入力 Inputs'!$B$57*(1+'入力 Inputs'!$B$91)^(7-1))*(1+'入力 Inputs'!$B$85)) -> 19209780 | K11: {=IF(A11="","",IF(A11<=10,J11*(1-INDEX('入力 Inputs'!$B$71:$B$80,A11)),J11))} -> 19209780 | L11: =IF(A11="","",J11) -> 19209780 | M11: =IF(A11="","",D11*'入力 Inputs'!$B$64) -> 2.9263718e+09 | N11: =A11 -> 7 | O11: =IF(A11="","",D11) -> 18289823 | P11: =IF(A11="","",G11) -> 18590148 | Q11: =IF(A11="","",J11) -> 19209780
A12: =IF(8<='入力 Inputs'!$B$86,8,"") -> 8 | B12: =IF(A12="","",'入力 Inputs'!$B$55+A12) -> 54 | C12: =IF(A12="","",0) -> 0 | D12: =IF(A12="","",(D11-D11*'入力 Inputs'!$B$41-'入力 Inputs'!$B$57*(1+'入力 Inputs'!$B$91)^(8-1))*(1+'入力 Inputs'!$B$83)) -> 19404090 | E12: {=IF(A12="","",IF(A12<=10,D12*(1-INDEX('入力 Inputs'!$B$71:$B$80,A12)),D12))} -> 19404090 | F12: =IF(A12="","",D12) -> 19404090 | G12: =IF(A12="","",(G11-G11*'入力 Inputs'!$B$41-'入力 Inputs'!$B$57*(1+'入力 Inputs'!$B$91)^(8-1))*(1+'入力 Inputs'!$B$84)) -> 19768655 | H12: {=IF(A12="","",IF(A12<=10,G12*(1-INDEX('入力 Inputs'!$B$71:$B$80,A12)),G12))} -> 19768655 | I12: =IF(A12="","",G12) -> 19768655 | J12: =IF(A12="","",(J11-J11*'入力 Inputs'!$B$41-'入力 Inputs'!$B$57*(1+'入力 Inputs'!$B$91)^(8-1))*(1+'入力 Inputs'!$B$85)) -> 20523477 | K12: {=IF(A12="","",IF(A12<=10,J12*(1-INDEX('入力 Inputs'!$B$71:$B$80,A12)),J12))} -> 20523477 | L12: =IF(A12="","",J12) -> 20523477 | M12: =IF(A12="","",D12*'入力 Inputs'!$B$64) -> 3.1046543e+09 | N12: =A12 -> 8 | O12: =IF(A12="","",D12) -> 19404090 | P12: =IF(A12="","",G12) -> 19768655 | Q12: =IF(A12="","",J12) -> 20523477
A13: =IF(9<='入力 Inputs'!$B$86,9,"") -> 9 | B13: =IF(A13="","",'入力 Inputs'!$B$55+A13) -> 55 | C13: =IF(A13="","",0) -> 0 | D13: =IF(A13="","",(D12-D12*'入力 Inputs'!$B$41-'入力 Inputs'!$B$57*(1+'入力 Inputs'!$B$91)^(9-1))*(1+'入力 Inputs'!$B$83)) -> 20586245 | E13: {=IF(A13="","",IF(A13<=10,D13*(1-INDEX('入力 Inputs'!$B$71:$B$80,A13)),D13))} -> 20586245 | F13: =IF(A13="","",D13) -> 20586245 | G13: =IF(A13="","",(G12-G12*'入力 Inputs'!$B$41-'入力 Inputs'!$B$57*(1+'入力 Inputs'!$B$91)^(9-1))*(1+'入力 Inputs'!$B$84)) -> 21021877 | H13: {=IF(A13="","",IF(A13<=10,G13*(1-INDEX('入力 Inputs'!$B$71:$B$80,A13)),G13))} -> 21021877 | I13: =IF(A13="","",G13) -> 21021877 | J13: =IF(A13="","",(J12-J12*'入力 Inputs'!$B$41-'入力 Inputs'!$B$57*(1+'入力 Inputs'!$B$91)^(9-1))*(1+'入力 Inputs'!$B$85)) -> 21927020 | K13: {=IF(A13="","",IF(A13<=10,J13*(1-INDEX('入力 Inputs'!$B$71:$B$80,A13)),J13))} -> 21927020 | L13: =IF(A13="","",J13) -> 21927020 | M13: =IF(A13="","",D13*'入力 Inputs'!$B$64) -> 3.2937992e+09 | N13: =A13 -> 9 | O13: =IF(A13="","",D13) -> 20586245 | P13: =IF(A13="","",G13) -> 21021877 | Q13: =IF(A13="","",J13) -> 21927020
A14: =IF(10<='入力 Inputs'!$B$86,10,"") -> 10 | B14: =IF(A14="","",'入力 Inputs'!$B$55+A14) -> 56 | C14: =IF(A14="","",0) -> 0 | D14: =IF(A14="","",(D13-D13*'入力 Inputs'!$B$41-'入力 Inputs'!$B$57*(1+'入力 Inputs'!$B$91)^(10-1))*(1+'入力 Inputs'!$B$83)) -> 21840425 | E14: {=IF(A14="","",IF(A14<=10,D14*(1-INDEX('入力 Inputs'!$B$71:$B$80,A14)),D14))} -> 21840425 | F14: =IF(A14="","",D14) -> 21840425 | G14: =IF(A14="","",(G13-G13*'入力 Inputs'!$B$41-'入力 Inputs'!$B$57*(1+'入力 Inputs'!$B$91)^(10-1))*(1+'入力 Inputs'!$B$84)) -> 22354552 | H14: {=IF(A14="","",IF(A14<=10,G14*(1-INDEX('入力 Inputs'!$B$71:$B$80,A14)),G14))} -> 22354552 | I14: =IF(A14="","",G14) -> 22354552 | J14: =IF(A14="","",(J13-J13*'入力 Inputs'!$B$41-'入力 Inputs'!$B$57*(1+'入力 Inputs'!$B$91)^(10-1))*(1+'入力 Inputs'!$B$85)) -> 23426553 | K14: {=IF(A14="","",IF(A14<=10,J14*(1-INDEX('入力 Inputs'!$B$71:$B$80,A14)),J14))} -> 23426553 | L14: =IF(A14="","",J14) -> 23426553 | M14: =IF(A14="","",D14*'入力 Inputs'!$B$64) -> 3.494468e+09 | N14: =A14 -> 10 | O14: =IF(A14="","",D14) -> 21840425 | P14: =IF(A14="","",G14) -> 22354552 | Q14: =IF(A14="","",J14) -> 23426553
A15: =IF(11<='入力 Inputs'!$B$86,11,"") -> 11 | B15: =IF(A15="","",'入力 Inputs'!$B$55+A15) -> 57 | C15: =IF(A15="","",0) -> 0 | D15: =IF(A15="","",(D14-D14*'入力 Inputs'!$B$41-'入力 Inputs'!$B$57*(1+'入力 Inputs'!$B$91)^(11-1))*(1+'入力 Inputs'!$B$83)) -> 23171020 | E15: {=IF(A15="","",IF(A15<=10,D15*(1-INDEX('入力 Inputs'!$B$71:$B$80,A15)),D15))} -> 23171020 | F15: =IF(A15="","",D15) -> 23171020 | G15: =IF(A15="","",(G14-G14*'入力 Inputs'!$B$41-'入力 Inputs'!$B$57*(1+'入力 Inputs'!$B$91)^(11-1))*(1+'入力 Inputs'!$B$84)) -> 23771716 | H15: {=IF(A15="","",IF(A15<=10,G15*(1-INDEX('入力 Inputs'!$B$71:$B$80,A15)),G15))} -> 23771716 | I15: =IF(A15="","",G15) -> 23771716 | J15: =IF(A15="","",(J14-J14*'入力 Inputs'!$B$41-'入力 Inputs'!$B$57*(1+'入力 Inputs'!$B$91)^(11-1))*(1+'入力 Inputs'!$B$85)) -> 25028641 | K15: {=IF(A15="","",IF(A15<=10,J15*(1-INDEX('入力 Inputs'!$B$71:$B$80,A15)),J15))} -> 25028641 | L15: =IF(A15="","",J15) -> 25028641 | M15: =IF(A15="","",D15*'入力 Inputs'!$B$64) -> 3.7073631e+09 | N15: =A15 -> 11 | O15: =IF(A15="","",D15) -> 23171020 | P15: =IF(A15="","",G15) -> 23771716 | Q15: =IF(A15="","",J15) -> 25028641
A16: =IF(12<='入力 Inputs'!$B$86,12,"") -> 12 | B16: =IF(A16="","",'入力 Inputs'!$B$55+A16) -> 58 | C16: =IF(A16="","",0) -> 0 | D16: =IF(A16="","",(D15-D15*'入力 Inputs'!$B$41-'入力 Inputs'!$B$57*(1+'入力 Inputs'!$B$91)^(12-1))*(1+'入力 Inputs'!$B$83)) -> 24582683 | E16: {=IF(A16="","",IF(A16<=10,D16*(1-INDEX('入力 Inputs'!$B$71:$B$80,A16)),D16))} -> 24582683 | F16: =IF(A16="","",D16) -> 24582683 | G16: =IF(A16="","",(G15-G15*'入力 Inputs'!$B$41-'入力 Inputs'!$B$57*(1+'入力 Inputs'!$B$91)^(12-1))*(1+'入力 Inputs'!$B$84)) -> 25278728 | H16: {=IF(A16="","",IF(A16<=10,G16*(1-INDEX('入力 Inputs'!$B$71:$B$80,A16)),G16))} -> 25278728 | I16: =IF(A16="","",G16) -> 25278728 | J16: =IF(A16="","",(J15-J15*'入力 Inputs'!$B$41-'入力 Inputs'!$B$57*(1+'入力 Inputs'!$B$91)^(12-1))*(1+'入力 Inputs'!$B$85)) -> 26740300 | K16: {=IF(A16="","",IF(A16<=10,J16*(1-INDEX('入力 Inputs'!$B$71:$B$80,A16)),J16))} -> 26740300 | L16: =IF(A16="","",J16) -> 26740300 | M16: =IF(A16="","",D16*'入力 Inputs'!$B$64) -> 3.9332294e+09 | N16: =A16 -> 12 | O16: =IF(A16="","",D16) -> 24582683 | P16: =IF(A16="","",G16) -> 25278728 | Q16: =IF(A16="","",J16) -> 26740300
A17: =IF(13<='入力 Inputs'!$B$86,13,"") -> 13 | B17: =IF(A17="","",'入力 Inputs'!$B$55+A17) -> 59 | C17: =IF(A17="","",0) -> 0 | D17: =IF(A17="","",(D16-D16*'入力 Inputs'!$B$41-'入力 Inputs'!$B$57*(1+'入力 Inputs'!$B$91)^(13-1))*(1+'入力 Inputs'!$B$83)) -> 26080357 | E17: {=IF(A17="","",IF(A17<=10,D17*(1-INDEX('入力 Inputs'!$B$71:$B$80,A17)),D17))} -> 26080357 | F17: =IF(A17="","",D17) -> 26080357 | G17: =IF(A17="","",(G16-G16*'入力 Inputs'!$B$41-'入力 Inputs'!$B$57*(1+'入力 Inputs'!$B$91)^(13-1))*(1+'入力 Inputs'!$B$84)) -> 26881282 | H17: {=IF(A17="","",IF(A17<=10,G17*(1-INDEX('入力 Inputs'!$B$71:$B$80,A17)),G17))} -> 26881282 | I17: =IF(A17="","",G17) -> 26881282 | J17: =IF(A17="","",(J16-J16*'入力 Inputs'!$B$41-'入力 Inputs'!$B$57*(1+'入力 Inputs'!$B$91)^(13-1))*(1+'入力 Inputs'!$B$85)) -> 28569022 | K17: {=IF(A17="","",IF(A17<=10,J17*(1-INDEX('入力 Inputs'!$B$71:$B$80,A17)),J17))} -> 28569022 | L17: =IF(A17="","",J17) -> 28569022 | M17: =IF(A17="","",D17*'入力 Inputs'!$B$64) -> 4.1728571e+09 | N17: =A17 -> 13 | O17: =IF(A17="","",D17) -> 26080357 | P17: =IF(A17="","",G17) -> 26881282 | Q17: =IF(A17="","",J17) -> 28569022
A18: =IF(14<='入力 Inputs'!$B$86,14,"") -> 14 | B18: =IF(A18="","",'入力 Inputs'!$B$55+A18) -> 60 | C18: =IF(A18="","",0) -> 0 | D18: =IF(A18="","",(D17-D17*'入力 Inputs'!$B$41-'入力 Inputs'!$B$57*(1+'入力 Inputs'!$B$91)^(14-1))*(1+'入力 Inputs'!$B$83)) -> 27669279 | E18: {=IF(A18="","",IF(A18<=10,D18*(1-INDEX('入力 Inputs'!$B$71:$B$80,A18)),D18))} -> 27669279 | F18: =IF(A18="","",D18) -> 27669279 | G18: =IF(A18="","",(G17-G17*'入力 Inputs'!$B$41-'入力 Inputs'!$B$57*(1+'入力 Inputs'!$B$91)^(14-1))*(1+'入力 Inputs'!$B$84)) -> 28585437 | H18: {=IF(A18="","",IF(A18<=10,G18*(1-INDEX('入力 Inputs'!$B$71:$B$80,A18)),G18))} -> 28585437 | I18: =IF(A18="","",G18) -> 28585437 | J18: =IF(A18="","",(J17-J17*'入力 Inputs'!$B$41-'入力 Inputs'!$B$57*(1+'入力 Inputs'!$B$91)^(14-1))*(1+'入力 Inputs'!$B$85)) -> 30522814 | K18: {=IF(A18="","",IF(A18<=10,J18*(1-INDEX('入力 Inputs'!$B$71:$B$80,A18)),J18))} -> 30522814 | L18: =IF(A18="","",J18) -> 30522814 | M18: =IF(A18="","",D18*'入力 Inputs'!$B$64) -> 4.4270847e+09 | N18: =A18 -> 14 | O18: =IF(A18="","",D18) -> 27669279 | P18: =IF(A18="","",G18) -> 28585437 | Q18: =IF(A18="","",J18) -> 30522814
A19: =IF(15<='入力 Inputs'!$B$86,15,"") -> 15 | B19: =IF(A19="","",'入力 Inputs'!$B$55+A19) -> 61 | C19: =IF(A19="","",0) -> 0 | D19: =IF(A19="","",(D18-D18*'入力 Inputs'!$B$41-'入力 Inputs'!$B$57*(1+'入力 Inputs'!$B$91)^(15-1))*(1+'入力 Inputs'!$B$83)) -> 29355011 | E19: {=IF(A19="","",IF(A19<=10,D19*(1-INDEX('入力 Inputs'!$B$71:$B$80,A19)),D19))} -> 29355011 | F19: =IF(A19="","",D19) -> 29355011 | G19: =IF(A19="","",(G18-G18*'入力 Inputs'!$B$41-'入力 Inputs'!$B$57*(1+'入力 Inputs'!$B$91)^(15-1))*(1+'入力 Inputs'!$B$84)) -> 30397635 | H19: {=IF(A19="","",IF(A19<=10,G19*(1-INDEX('入力 Inputs'!$B$71:$B$80,A19)),G19))} -> 30397635 | I19: =IF(A19="","",G19) -> 30397635 | J19: =IF(A19="","",(J18-J18*'入力 Inputs'!$B$41-'入力 Inputs'!$B$57*(1+'入力 Inputs'!$B$91)^(15-1))*(1+'入力 Inputs'!$B$85)) -> 32610230 | K19: {=IF(A19="","",IF(A19<=10,J19*(1-INDEX('入力 Inputs'!$B$71:$B$80,A19)),J19))} -> 32610230 | L19: =IF(A19="","",J19) -> 32610230 | M19: =IF(A19="","",D19*'入力 Inputs'!$B$64) -> 4.6968018e+09 | N19: =A19 -> 15 | O19: =IF(A19="","",D19) -> 29355011 | P19: =IF(A19="","",G19) -> 30397635 | Q19: =IF(A19="","",J19) -> 32610230
A20: =IF(16<='入力 Inputs'!$B$86,16,"") -> 16 | B20: =IF(A20="","",'入力 Inputs'!$B$55+A20) -> 62 | C20: =IF(A20="","",0) -> 0 | D20: =IF(A20="","",(D19-D19*'入力 Inputs'!$B$41-'入力 Inputs'!$B$57*(1+'入力 Inputs'!$B$91)^(16-1))*(1+'入力 Inputs'!$B$83)) -> 31143452 | E20: {=IF(A20="","",IF(A20<=10,D20*(1-INDEX('入力 Inputs'!$B$71:$B$80,A20)),D20))} -> 31143452 | F20: =IF(A20="","",D20) -> 31143452 | G20: =IF(A20="","",(G19-G19*'入力 Inputs'!$B$41-'入力 Inputs'!$B$57*(1+'入力 Inputs'!$B$91)^(16-1))*(1+'入力 Inputs'!$B$84)) -> 32324724 | H20: {=IF(A20="","",IF(A20<=10,G20*(1-INDEX('入力 Inputs'!$B$71:$B$80,A20)),G20))} -> 32324724 | I20: =IF(A20="","",G20) -> 32324724 | J20: =IF(A20="","",(J19-J19*'入力 Inputs'!$B$41-'入力 Inputs'!$B$57*(1+'入力 Inputs'!$B$91)^(16-1))*(1+'入力 Inputs'!$B$85)) -> 34840409 | K20: {=IF(A20="","",IF(A20<=10,J20*(1-INDEX('入力 Inputs'!$B$71:$B$80,A20)),J20))} -> 34840409 | L20: =IF(A20="","",J20) -> 34840409 | M20: =IF(A20="","",D20*'入力 Inputs'!$B$64) -> 4.9829523e+09 | N20: =A20 -> 16 | O20: =IF(A20="","",D20) -> 31143452 | P20: =IF(A20="","",G20) -> 32324724 | Q20: =IF(A20="","",J20) -> 34840409
A21: =IF(17<='入力 Inputs'!$B$86,17,"") -> 17 | B21: =IF(A21="","",'入力 Inputs'!$B$55+A21) -> 63 | C21: =IF(A21="","",0) -> 0 | D21: =IF(A21="","",(D20-D20*'入力 Inputs'!$B$41-'入力 Inputs'!$B$57*(1+'入力 Inputs'!$B$91)^(17-1))*(1+'入力 Inputs'!$B$83)) -> 33040858 | E21: {=IF(A21="","",IF(A21<=10,D21*(1-INDEX('入力 Inputs'!$B$71:$B$80,A21)),D21))} -> 33040858 | F21: =IF(A21="","",D21) -> 33040858 | G21: =IF(A21="","",(G20-G20*'入力 Inputs'!$B$41-'入力 Inputs'!$B$57*(1+'入力 Inputs'!$B$91)^(17-1))*(1+'入力 Inputs'!$B$84)) -> 34373990 | H21: {=IF(A21="","",IF(A21<=10,G21*(1-INDEX('入力 Inputs'!$B$71:$B$80,A21)),G21))} -> 34373990 | I21: =IF(A21="","",G21) -> 34373990 | J21: =IF(A21="","",(J20-J20*'入力 Inputs'!$B$41-'入力 Inputs'!$B$57*(1+'入力 Inputs'!$B$91)^(17-1))*(1+'入力 Inputs'!$B$85)) -> 37223115 | K21: {=IF(A21="","",IF(A21<=10,J21*(1-INDEX('入力 Inputs'!$B$71:$B$80,A21)),J21))} -> 37223115 | L21: =IF(A21="","",J21) -> 37223115 | M21: =IF(A21="","",D21*'入力 Inputs'!$B$64) -> 5.2865372e+09 | N21: =A21 -> 17 | O21: =IF(A21="","",D21) -> 33040858 | P21: =IF(A21="","",G21) -> 34373990 | Q21: =IF(A21="","",J21) -> 37223115
A22: =IF(18<='入力 Inputs'!$B$86,18,"") -> 18 | B22: =IF(A22="","",'入力 Inputs'!$B$55+A22) -> 64 | C22: =IF(A22="","",0) -> 0 | D22: =IF(A22="","",(D21-D21*'入力 Inputs'!$B$41-'入力 Inputs'!$B$57*(1+'入力 Inputs'!$B$91)^(18-1))*(1+'入力 Inputs'!$B$83)) -> 35053869 | E22: {=IF(A22="","",IF(A22<=10,D22*(1-INDEX('入力 Inputs'!$B$71:$B$80,A22)),D22))} -> 35053869 | F22: =IF(A22="","",D22) -> 35053869 | G22: =IF(A22="","",(G21-G21*'入力 Inputs'!$B$41-'入力 Inputs'!$B$57*(1+'入力 Inputs'!$B$91)^(18-1))*(1+'入力 Inputs'!$B$84)) -> 36553178 | H22: {=IF(A22="","",IF(A22<=10,G22*(1-INDEX('入力 Inputs'!$B$71:$B$80,A22)),G22))} -> 36553178 | I22: =IF(A22="","",G22) -> 36553178 | J22: =IF(A22="","",(J21-J21*'入力 Inputs'!$B$41-'入力 Inputs'!$B$57*(1+'入力 Inputs'!$B$91)^(18-1))*(1+'入力 Inputs'!$B$85)) -> 39768780 | K22: {=IF(A22="","",IF(A22<=10,J22*(1-INDEX('入力 Inputs'!$B$71:$B$80,A22)),J22))} -> 39768780 | L22: =IF(A22="","",J22) -> 39768780 | M22: =IF(A22="","",D22*'入力 Inputs'!$B$64) -> 5.608619e+09 | N22: =A22 -> 18 | O22: =IF(A22="","",D22) -> 35053869 | P22: =IF(A22="","",G22) -> 36553178 | Q22: =IF(A22="","",J22) -> 39768780
A23: =IF(19<='入力 Inputs'!$B$86,19,"") -> 19 | B23: =IF(A23="","",'入力 Inputs'!$B$55+A23) -> 65 | C23: =IF(A23="","",0) -> 0 | D23: =IF(A23="","",(D22-D22*'入力 Inputs'!$B$41-'入力 Inputs'!$B$57*(1+'入力 Inputs'!$B$91)^(19-1))*(1+'入力 Inputs'!$B$83)) -> 37189529 | E23: {=IF(A23="","",IF(A23<=10,D23*(1-INDEX('入力 Inputs'!$B$71:$B$80,A23)),D23))} -> 37189529 | F23: =IF(A23="","",D23) -> 37189529 | G23: =IF(A23="","",(G22-G22*'入力 Inputs'!$B$41-'入力 Inputs'!$B$57*(1+'入力 Inputs'!$B$91)^(19-1))*(1+'入力 Inputs'!$B$84)) -> 38870526 | H23: {=IF(A23="","",IF(A23<=10,G23*(1-INDEX('入力 Inputs'!$B$71:$B$80,A23)),G23))} -> 38870526 | I23: =IF(A23="","",G23) -> 38870526 | J23: =IF(A23="","",(J22-J22*'入力 Inputs'!$B$41-'入力 Inputs'!$B$57*(1+'入力 Inputs'!$B$91)^(19-1))*(1+'入力 Inputs'!$B$85)) -> 42488550 | K23: {=IF(A23="","",IF(A23<=10,J23*(1-INDEX('入力 Inputs'!$B$71:$B$80,A23)),J23))} -> 42488550 | L23: =IF(A23="","",J23) -> 42488550 | M23: =IF(A23="","",D23*'入力 Inputs'!$B$64) -> 5.9503247e+09 | N23: =A23 -> 19 | O23: =IF(A23="","",D23) -> 37189529 | P23: =IF(A23="","",G23) -> 38870526 | Q23: =IF(A23="","",J23) -> 42488550
A24: =IF(20<='入力 Inputs'!$B$86,20,"") -> 20 | B24: =IF(A24="","",'入力 Inputs'!$B$55+A24) -> 66 | C24: =IF(A24="","",0) -> 0 | D24: =IF(A24="","",(D23-D23*'入力 Inputs'!$B$41-'入力 Inputs'!$B$57*(1+'入力 Inputs'!$B$91)^(20-1))*(1+'入力 Inputs'!$B$83)) -> 39455311 | E24: {=IF(A24="","",IF(A24<=10,D24*(1-INDEX('入力 Inputs'!$B$71:$B$80,A24)),D24))} -> 39455311 | F24: =IF(A24="","",D24) -> 39455311 | G24: =IF(A24="","",(G23-G23*'入力 Inputs'!$B$41-'入力 Inputs'!$B$57*(1+'入力 Inputs'!$B$91)^(20-1))*(1+'入力 Inputs'!$B$84)) -> 41334793 | H24: {=IF(A24="","",IF(A24<=10,G24*(1-INDEX('入力 Inputs'!$B$71:$B$80,A24)),G24))} -> 41334793 | I24: =IF(A24="","",G24) -> 41334793 | J24: =IF(A24="","",(J23-J23*'入力 Inputs'!$B$41-'入力 Inputs'!$B$57*(1+'入力 Inputs'!$B$91)^(20-1))*(1+'入力 Inputs'!$B$85)) -> 45394332 | K24: {=IF(A24="","",IF(A24<=10,J24*(1-INDEX('入力 Inputs'!$B$71:$B$80,A24)),J24))} -> 45394332 | L24: =IF(A24="","",J24) -> 45394332 | M24: =IF(A24="","",D24*'入力 Inputs'!$B$64) -> 6.3128498e+09 | N24: =A24 -> 20 | O24: =IF(A24="","",D24) -> 39455311 | P24: =IF(A24="","",G24) -> 41334793 | Q24: =IF(A24="","",J24) -> 45394332
A25: =IF(21<='入力 Inputs'!$B$86,21,"") -> 21 | B25: =IF(A25="","",'入力 Inputs'!$B$55+A25) -> 67 | C25: =IF(A25="","",0) -> 0 | D25: =IF(A25="","",(D24-D24*'入力 Inputs'!$B$41-'入力 Inputs'!$B$57*(1+'入力 Inputs'!$B$91)^(21-1))*(1+'入力 Inputs'!$B$83)) -> 41859144 | E25: {=IF(A25="","",IF(A25<=10,D25*(1-INDEX('入力 Inputs'!$B$71:$B$80,A25)),D25))} -> 41859144 | F25: =IF(A25="","",D25) -> 41859144 | G25: =IF(A25="","",(G24-G24*'入力 Inputs'!$B$41-'入力 Inputs'!$B$57*(1+'入力 Inputs'!$B$91)^(21-1))*(1+'入力 Inputs'!$B$84)) -> 43955294 | H25: {=IF(A25="","",IF(A25<=10,G25*(1-INDEX('入力 Inputs'!$B$71:$B$80,A25)),G25))} -> 43955294 | I25: =IF(A25="","",G25) -> 43955294 | J25: =IF(A25="","",(J24-J24*'入力 Inputs'!$B$41-'入力 Inputs'!$B$57*(1+'入力 Inputs'!$B$91)^(21-1))*(1+'入力 Inputs'!$B$85)) -> 48498848 | K25: {=IF(A25="","",IF(A25<=10,J25*(1-INDEX('入力 Inputs'!$B$71:$B$80,A25)),J25))} -> 48498848 | L25: =IF(A25="","",J25) -> 48498848 | M25: =IF(A25="","",D25*'入力 Inputs'!$B$64) -> 6.697463e+09 | N25: =A25 -> 21 | O25: =IF(A25="","",D25) -> 41859144 | P25: =IF(A25="","",G25) -> 43955294 | Q25: =IF(A25="","",J25) -> 48498848
A26: =IF(22<='入力 Inputs'!$B$86,22,"") -> 22 | B26: =IF(A26="","",'入力 Inputs'!$B$55+A26) -> 68 | C26: =IF(A26="","",0) -> 0 | D26: =IF(A26="","",(D25-D25*'入力 Inputs'!$B$41-'入力 Inputs'!$B$57*(1+'入力 Inputs'!$B$91)^(22-1))*(1+'入力 Inputs'!$B$83)) -> 44409438 | E26: {=IF(A26="","",IF(A26<=10,D26*(1-INDEX('入力 Inputs'!$B$71:$B$80,A26)),D26))} -> 44409438 | F26: =IF(A26="","",D26) -> 44409438 | G26: =IF(A26="","",(G25-G25*'入力 Inputs'!$B$41-'入力 Inputs'!$B$57*(1+'入力 Inputs'!$B$91)^(22-1))*(1+'入力 Inputs'!$B$84)) -> 46741934 | H26: {=IF(A26="","",IF(A26<=10,G26*(1-INDEX('入力 Inputs'!$B$71:$B$80,A26)),G26))} -> 46741934 | I26: =IF(A26="","",G26) -> 46741934 | J26: =IF(A26="","",(J25-J25*'入力 Inputs'!$B$41-'入力 Inputs'!$B$57*(1+'入力 Inputs'!$B$91)^(22-1))*(1+'入力 Inputs'!$B$85)) -> 51815690 | K26: {=IF(A26="","",IF(A26<=10,J26*(1-INDEX('入力 Inputs'!$B$71:$B$80,A26)),J26))} -> 51815690 | L26: =IF(A26="","",J26) -> 51815690 | M26: =IF(A26="","",D26*'入力 Inputs'!$B$64) -> 7.1055101e+09 | N26: =A26 -> 22 | O26: =IF(A26="","",D26) -> 44409438 | P26: =IF(A26="","",G26) -> 46741934 | Q26: =IF(A26="","",J26) -> 51815690
A27: =IF(23<='入力 Inputs'!$B$86,23,"") -> 23 | B27: =IF(A27="","",'入力 Inputs'!$B$55+A27) -> 69 | C27: =IF(A27="","",0) -> 0 | D27: =IF(A27="","",(D26-D26*'入力 Inputs'!$B$41-'入力 Inputs'!$B$57*(1+'入力 Inputs'!$B$91)^(23-1))*(1+'入力 Inputs'!$B$83)) -> 47115117 | E27: {=IF(A27="","",IF(A27<=10,D27*(1-INDEX('入力 Inputs'!$B$71:$B$80,A27)),D27))} -> 47115117 | F27: =IF(A27="","",D27) -> 47115117 | G27: =IF(A27="","",(G26-G26*'入力 Inputs'!$B$41-'入力 Inputs'!$B$57*(1+'入力 Inputs'!$B$91)^(23-1))*(1+'入力 Inputs'!$B$84)) -> 49705248 | H27: {=IF(A27="","",IF(A27<=10,G27*(1-INDEX('入力 Inputs'!$B$71:$B$80,A27)),G27))} -> 49705248 | I27: =IF(A27="","",G27) -> 49705248 | J27: =IF(A27="","",(J26-J26*'入力 Inputs'!$B$41-'入力 Inputs'!$B$57*(1+'入力 Inputs'!$B$91)^(23-1))*(1+'入力 Inputs'!$B$85)) -> 55359381 | K27: {=IF(A27="","",IF(A27<=10,J27*(1-INDEX('入力 Inputs'!$B$71:$B$80,A27)),J27))} -> 55359381 | L27: =IF(A27="","",J27) -> 55359381 | M27: =IF(A27="","",D27*'入力 Inputs'!$B$64) -> 7.5384188e+09 | N27: =A27 -> 23 | O27: =IF(A27="","",D27) -> 47115117 | P27: =IF(A27="","",G27) -> 49705248 | Q27: =IF(A27="","",J27) -> 55359381
A28: =IF(24<='入力 Inputs'!$B$86,24,"") -> 24 | B28: =IF(A28="","",'入力 Inputs'!$B$55+A28) -> 70 | C28: =IF(A28="","",0) -> 0 | D28: =IF(A28="","",(D27-D27*'入力 Inputs'!$B$41-'入力 Inputs'!$B$57*(1+'入力 Inputs'!$B$91)^(24-1))*(1+'入力 Inputs'!$B$83)) -> 49985650 | E28: {=IF(A28="","",IF(A28<=10,D28*(1-INDEX('入力 Inputs'!$B$71:$B$80,A28)),D28))} -> 49985650 | F28: =IF(A28="","",D28) -> 49985650 | G28: =IF(A28="","",(G27-G27*'入力 Inputs'!$B$41-'入力 Inputs'!$B$57*(1+'入力 Inputs'!$B$91)^(24-1))*(1+'入力 Inputs'!$B$84)) -> 52856436 | H28: {=IF(A28="","",IF(A28<=10,G28*(1-INDEX('入力 Inputs'!$B$71:$B$80,A28)),G28))} -> 52856436 | I28: =IF(A28="","",G28) -> 52856436 | J28: =IF(A28="","",(J27-J27*'入力 Inputs'!$B$41-'入力 Inputs'!$B$57*(1+'入力 Inputs'!$B$91)^(24-1))*(1+'入力 Inputs'!$B$85)) -> 59145436 | K28: {=IF(A28="","",IF(A28<=10,J28*(1-INDEX('入力 Inputs'!$B$71:$B$80,A28)),J28))} -> 59145436 | L28: =IF(A28="","",J28) -> 59145436 | M28: =IF(A28="","",D28*'入力 Inputs'!$B$64) -> 7.997704e+09 | N28: =A28 -> 24 | O28: =IF(A28="","",D28) -> 49985650 | P28: =IF(A28="","",G28) -> 52856436 | Q28: =IF(A28="","",J28) -> 59145436
A29: =IF(25<='入力 Inputs'!$B$86,25,"") -> 25 | B29: =IF(A29="","",'入力 Inputs'!$B$55+A29) -> 71 | C29: =IF(A29="","",0) -> 0 | D29: =IF(A29="","",(D28-D28*'入力 Inputs'!$B$41-'入力 Inputs'!$B$57*(1+'入力 Inputs'!$B$91)^(25-1))*(1+'入力 Inputs'!$B$83)) -> 53031080 | E29: {=IF(A29="","",IF(A29<=10,D29*(1-INDEX('入力 Inputs'!$B$71:$B$80,A29)),D29))} -> 53031080 | F29: =IF(A29="","",D29) -> 53031080 | G29: =IF(A29="","",(G28-G28*'入力 Inputs'!$B$41-'入力 Inputs'!$B$57*(1+'入力 Inputs'!$B$91)^(25-1))*(1+'入力 Inputs'!$B$84)) -> 56207409 | H29: {=IF(A29="","",IF(A29<=10,G29*(1-INDEX('入力 Inputs'!$B$71:$B$80,A29)),G29))} -> 56207409 | I29: =IF(A29="","",G29) -> 56207409 | J29: =IF(A29="","",(J28-J28*'入力 Inputs'!$B$41-'入力 Inputs'!$B$57*(1+'入力 Inputs'!$B$91)^(25-1))*(1+'入力 Inputs'!$B$85)) -> 63190430 | K29: {=IF(A29="","",IF(A29<=10,J29*(1-INDEX('入力 Inputs'!$B$71:$B$80,A29)),J29))} -> 63190430 | L29: =IF(A29="","",J29) -> 63190430 | M29: =IF(A29="","",D29*'入力 Inputs'!$B$64) -> 8.4849728e+09 | N29: =A29 -> 25 | O29: =IF(A29="","",D29) -> 53031080 | P29: =IF(A29="","",G29) -> 56207409 | Q29: =IF(A29="","",J29) -> 63190430
A30: =IF(26<='入力 Inputs'!$B$86,26,"") -> 26 | B30: =IF(A30="","",'入力 Inputs'!$B$55+A30) -> 72 | C30: =IF(A30="","",0) -> 0 | D30: =IF(A30="","",(D29-D29*'入力 Inputs'!$B$41-'入力 Inputs'!$B$57*(1+'入力 Inputs'!$B$91)^(26-1))*(1+'入力 Inputs'!$B$83)) -> 56262064 | E30: {=IF(A30="","",IF(A30<=10,D30*(1-INDEX('入力 Inputs'!$B$71:$B$80,A30)),D30))} -> 56262064 | F30: =IF(A30="","",D30) -> 56262064 | G30: =IF(A30="","",(G29-G29*'入力 Inputs'!$B$41-'入力 Inputs'!$B$57*(1+'入力 Inputs'!$B$91)^(26-1))*(1+'入力 Inputs'!$B$84)) -> 59770835 | H30: {=IF(A30="","",IF(A30<=10,G30*(1-INDEX('入力 Inputs'!$B$71:$B$80,A30)),G30))} -> 59770835 | I30: =IF(A30="","",G30) -> 59770835 | J30: =IF(A30="","",(J29-J29*'入力 Inputs'!$B$41-'入力 Inputs'!$B$57*(1+'入力 Inputs'!$B$91)^(26-1))*(1+'入力 Inputs'!$B$85)) -> 67512074 | K30: {=IF(A30="","",IF(A30<=10,J30*(1-INDEX('入力 Inputs'!$B$71:$B$80,A30)),J30))} -> 67512074 | L30: =IF(A30="","",J30) -> 67512074 | M30: =IF(A30="","",D30*'入力 Inputs'!$B$64) -> 9.0019303e+09 | N30: =A30 -> 26 | O30: =IF(A30="","",D30) -> 56262064 | P30: =IF(A30="","",G30) -> 59770835 | Q30: =IF(A30="","",J30) -> 67512074
A31: =IF(27<='入力 Inputs'!$B$86,27,"") -> 27 | B31: =IF(A31="","",'入力 Inputs'!$B$55+A31) -> 73 | C31: =IF(A31="","",0) -> 0 | D31: =IF(A31="","",(D30-D30*'入力 Inputs'!$B$41-'入力 Inputs'!$B$57*(1+'入力 Inputs'!$B$91)^(27-1))*(1+'入力 Inputs'!$B$83)) -> 59689909 | E31: {=IF(A31="","",IF(A31<=10,D31*(1-INDEX('入力 Inputs'!$B$71:$B$80,A31)),D31))} -> 59689909 | F31: =IF(A31="","",D31) -> 59689909 | G31: =IF(A31="","",(G30-G30*'入力 Inputs'!$B$41-'入力 Inputs'!$B$57*(1+'入力 Inputs'!$B$91)^(27-1))*(1+'入力 Inputs'!$B$84)) -> 63560183 | H31: {=IF(A31="","",IF(A31<=10,G31*(1-INDEX('入力 Inputs'!$B$71:$B$80,A31)),G31))} -> 63560183 | I31: =IF(A31="","",G31) -> 63560183 | J31: =IF(A31="","",(J30-J30*'入力 Inputs'!$B$41-'入力 Inputs'!$B$57*(1+'入力 Inputs'!$B$91)^(27-1))*(1+'入力 Inputs'!$B$85)) -> 72129289 | K31: {=IF(A31="","",IF(A31<=10,J31*(1-INDEX('入力 Inputs'!$B$71:$B$80,A31)),J31))} -> 72129289 | L31: =IF(A31="","",J31) -> 72129289 | M31: =IF(A31="","",D31*'入力 Inputs'!$B$64) -> 9.5503854e+09 | N31: =A31 -> 27 | O31: =IF(A31="","",D31) -> 59689909 | P31: =IF(A31="","",G31) -> 63560183 | Q31: =IF(A31="","",J31) -> 72129289
A32: =IF(28<='入力 Inputs'!$B$86,28,"") -> 28 | B32: =IF(A32="","",'入力 Inputs'!$B$55+A32) -> 74 | C32: =IF(A32="","",0) -> 0 | D32: =IF(A32="","",(D31-D31*'入力 Inputs'!$B$41-'入力 Inputs'!$B$57*(1+'入力 Inputs'!$B$91)^(28-1))*(1+'入力 Inputs'!$B$83)) -> 63326607 | E32: {=IF(A32="","",IF(A32<=10,D32*(1-INDEX('入力 Inputs'!$B$71:$B$80,A32)),D32))} -> 63326607 | F32: =IF(A32="","",D32) -> 63326607 | G32: =IF(A32="","",(G31-G31*'入力 Inputs'!$B$41-'入力 Inputs'!$B$57*(1+'入力 Inputs'!$B$91)^(28-1))*(1+'入力 Inputs'!$B$84)) -> 67589777 | H32: {=IF(A32="","",IF(A32<=10,G32*(1-INDEX('入力 Inputs'!$B$71:$B$80,A32)),G32))} -> 67589777 | I32: =IF(A32="","",G32) -> 67589777 | J32: =IF(A32="","",(J31-J31*'入力 Inputs'!$B$41-'入力 Inputs'!$B$57*(1+'入力 Inputs'!$B$91)^(28-1))*(1+'入力 Inputs'!$B$85)) -> 77062290 | K32: {=IF(A32="","",IF(A32<=10,J32*(1-INDEX('入力 Inputs'!$B$71:$B$80,A32)),J32))} -> 77062290 | L32: =IF(A32="","",J32) -> 77062290 | M32: =IF(A32="","",D32*'入力 Inputs'!$B$64) -> 1.0132257e+10 | N32: =A32 -> 28 | O32: =IF(A32="","",D32) -> 63326607 | P32: =IF(A32="","",G32) -> 67589777 | Q32: =IF(A32="","",J32) -> 77062290
A33: =IF(29<='入力 Inputs'!$B$86,29,"") -> 29 | B33: =IF(A33="","",'入力 Inputs'!$B$55+A33) -> 75 | C33: =IF(A33="","",0) -> 0 | D33: =IF(A33="","",(D32-D32*'入力 Inputs'!$B$41-'入力 Inputs'!$B$57*(1+'入力 Inputs'!$B$91)^(29-1))*(1+'入力 Inputs'!$B$83)) -> 67184886 | E33: {=IF(A33="","",IF(A33<=10,D33*(1-INDEX('入力 Inputs'!$B$71:$B$80,A33)),D33))} -> 67184886 | F33: =IF(A33="","",D33) -> 67184886 | G33: =IF(A33="","",(G32-G32*'入力 Inputs'!$B$41-'入力 Inputs'!$B$57*(1+'入力 Inputs'!$B$91)^(29-1))*(1+'入力 Inputs'!$B$84)) -> 71874849 | H33: {=IF(A33="","",IF(A33<=10,G33*(1-INDEX('入力 Inputs'!$B$71:$B$80,A33)),G33))} -> 71874849 | I33: =IF(A33="","",G33) -> 71874849 | J33: =IF(A33="","",(J32-J32*'入力 Inputs'!$B$41-'入力 Inputs'!$B$57*(1+'入力 Inputs'!$B$91)^(29-1))*(1+'入力 Inputs'!$B$85)) -> 82332675 | K33: {=IF(A33="","",IF(A33<=10,J33*(1-INDEX('入力 Inputs'!$B$71:$B$80,A33)),J33))} -> 82332675 | L33: =IF(A33="","",J33) -> 82332675 | M33: =IF(A33="","",D33*'入力 Inputs'!$B$64) -> 1.0749582e+10 | N33: =A33 -> 29 | O33: =IF(A33="","",D33) -> 67184886 | P33: =IF(A33="","",G33) -> 71874849 | Q33: =IF(A33="","",J33) -> 82332675
A34: =IF(30<='入力 Inputs'!$B$86,30,"") -> 30 | B34: =IF(A34="","",'入力 Inputs'!$B$55+A34) -> 76 | C34: =IF(A34="","",0) -> 0 | D34: =IF(A34="","",(D33-D33*'入力 Inputs'!$B$41-'入力 Inputs'!$B$57*(1+'入力 Inputs'!$B$91)^(30-1))*(1+'入力 Inputs'!$B$83)) -> 71278246 | E34: {=IF(A34="","",IF(A34<=10,D34*(1-INDEX('入力 Inputs'!$B$71:$B$80,A34)),D34))} -> 71278246 | F34: =IF(A34="","",D34) -> 71278246 | G34: =IF(A34="","",(G33-G33*'入力 Inputs'!$B$41-'入力 Inputs'!$B$57*(1+'入力 Inputs'!$B$91)^(30-1))*(1+'入力 Inputs'!$B$84)) -> 76431597 | H34: {=IF(A34="","",IF(A34<=10,G34*(1-INDEX('入力 Inputs'!$B$71:$B$80,A34)),G34))} -> 76431597 | I34: =IF(A34="","",G34) -> 76431597 | J34: =IF(A34="","",(J33-J33*'入力 Inputs'!$B$41-'入力 Inputs'!$B$57*(1+'入力 Inputs'!$B$91)^(30-1))*(1+'入力 Inputs'!$B$85)) -> 87963519 | K34: {=IF(A34="","",IF(A34<=10,J34*(1-INDEX('入力 Inputs'!$B$71:$B$80,A34)),J34))} -> 87963519 | L34: =IF(A34="","",J34) -> 87963519 | M34: =IF(A34="","",D34*'入力 Inputs'!$B$64) -> 1.1404519e+10 | N34: =A34 -> 30 | O34: =IF(A34="","",D34) -> 71278246 | P34: =IF(A34="","",G34) -> 76431597 | Q34: =IF(A34="","",J34) -> 87963519
A35: =IF(31<='入力 Inputs'!$B$86,31,"") -> 31 | B35: =IF(A35="","",'入力 Inputs'!$B$55+A35) -> 77 | C35: =IF(A35="","",0) -> 0 | D35: =IF(A35="","",(D34-D34*'入力 Inputs'!$B$41-'入力 Inputs'!$B$57*(1+'入力 Inputs'!$B$91)^(31-1))*(1+'入力 Inputs'!$B$83)) -> 75621010 | E35: {=IF(A35="","",IF(A35<=10,D35*(1-INDEX('入力 Inputs'!$B$71:$B$80,A35)),D35))} -> 75621010 | F35: =IF(A35="","",D35) -> 75621010 | G35: =IF(A35="","",(G34-G34*'入力 Inputs'!$B$41-'入力 Inputs'!$B$57*(1+'入力 Inputs'!$B$91)^(31-1))*(1+'入力 Inputs'!$B$84)) -> 81277244 | H35: {=IF(A35="","",IF(A35<=10,G35*(1-INDEX('入力 Inputs'!$B$71:$B$80,A35)),G35))} -> 81277244 | I35: =IF(A35="","",G35) -> 81277244 | J35: =IF(A35="","",(J34-J34*'入力 Inputs'!$B$41-'入力 Inputs'!$B$57*(1+'入力 Inputs'!$B$91)^(31-1))*(1+'入力 Inputs'!$B$85)) -> 93979476 | K35: {=IF(A35="","",IF(A35<=10,J35*(1-INDEX('入力 Inputs'!$B$71:$B$80,A35)),J35))} -> 93979476 | L35: =IF(A35="","",J35) -> 93979476 | M35: =IF(A35="","",D35*'入力 Inputs'!$B$64) -> 1.2099362e+10 | N35: =A35 -> 31 | O35: =IF(A35="","",D35) -> 75621010 | P35: =IF(A35="","",G35) -> 81277244 | Q35: =IF(A35="","",J35) -> 93979476
A36: =IF(32<='入力 Inputs'!$B$86,32,"") -> 32 | B36: =IF(A36="","",'入力 Inputs'!$B$55+A36) -> 78 | C36: =IF(A36="","",0) -> 0 | D36: =IF(A36="","",(D35-D35*'入力 Inputs'!$B$41-'入力 Inputs'!$B$57*(1+'入力 Inputs'!$B$91)^(32-1))*(1+'入力 Inputs'!$B$83)) -> 80228375 | E36: {=IF(A36="","",IF(A36<=10,D36*(1-INDEX('入力 Inputs'!$B$71:$B$80,A36)),D36))} -> 80228375 | F36: =IF(A36="","",D36) -> 80228375 | G36: =IF(A36="","",(G35-G35*'入力 Inputs'!$B$41-'入力 Inputs'!$B$57*(1+'入力 Inputs'!$B$91)^(32-1))*(1+'入力 Inputs'!$B$84)) -> 86430109 | H36: {=IF(A36="","",IF(A36<=10,G36*(1-INDEX('入力 Inputs'!$B$71:$B$80,A36)),G36))} -> 86430109 | I36: =IF(A36="","",G36) -> 86430109 | J36: =IF(A36="","",(J35-J35*'入力 Inputs'!$B$41-'入力 Inputs'!$B$57*(1+'入力 Inputs'!$B$91)^(32-1))*(1+'入力 Inputs'!$B$85)) -> 1.0040688e+08 | K36: {=IF(A36="","",IF(A36<=10,J36*(1-INDEX('入力 Inputs'!$B$71:$B$80,A36)),J36))} -> 1.0040688e+08 | L36: =IF(A36="","",J36) -> 1.0040688e+08 | M36: =IF(A36="","",D36*'入力 Inputs'!$B$64) -> 1.283654e+10 | N36: =A36 -> 32 | O36: =IF(A36="","",D36) -> 80228375 | P36: =IF(A36="","",G36) -> 86430109 | Q36: =IF(A36="","",J36) -> 1.0040688e+08
A37: =IF(33<='入力 Inputs'!$B$86,33,"") -> 33 | B37: =IF(A37="","",'入力 Inputs'!$B$55+A37) -> 79 | C37: =IF(A37="","",0) -> 0 | D37: =IF(A37="","",(D36-D36*'入力 Inputs'!$B$41-'入力 Inputs'!$B$57*(1+'入力 Inputs'!$B$91)^(33-1))*(1+'入力 Inputs'!$B$83)) -> 85116462 | E37: {=IF(A37="","",IF(A37<=10,D37*(1-INDEX('入力 Inputs'!$B$71:$B$80,A37)),D37))} -> 85116462 | F37: =IF(A37="","",D37) -> 85116462 | G37: =IF(A37="","",(G36-G36*'入力 Inputs'!$B$41-'入力 Inputs'!$B$57*(1+'入力 Inputs'!$B$91)^(33-1))*(1+'入力 Inputs'!$B$84)) -> 91909669 | H37: {=IF(A37="","",IF(A37<=10,G37*(1-INDEX('入力 Inputs'!$B$71:$B$80,A37)),G37))} -> 91909669 | I37: =IF(A37="","",G37) -> 91909669 | J37: =IF(A37="","",(J36-J36*'入力 Inputs'!$B$41-'入力 Inputs'!$B$57*(1+'入力 Inputs'!$B$91)^(33-1))*(1+'入力 Inputs'!$B$85)) -> 1.0727389e+08 | K37: {=IF(A37="","",IF(A37<=10,J37*(1-INDEX('入力 Inputs'!$B$71:$B$80,A37)),J37))} -> 1.0727389e+08 | L37: =IF(A37="","",J37) -> 1.0727389e+08 | M37: =IF(A37="","",D37*'入力 Inputs'!$B$64) -> 1.3618634e+10 | N37: =A37 -> 33 | O37: =IF(A37="","",D37) -> 85116462 | P37: =IF(A37="","",G37) -> 91909669 | Q37: =IF(A37="","",J37) -> 1.0727389e+08
